<?xml version="1.0"?>
<robot name="srm_buggy" xmlns:xacro="http://www.ros.org/wiki/xacro">

  <material name="white"><color rgba="1 1 1 1"/></material>
  <material name="black"><color rgba="0 0 0 1"/></material>
  <material name="blue"><color rgba="0.2 0.4 0.8 1"/></material>
  <material name="grey"><color rgba="0.5 0.5 0.5 1"/></material>

  <link name="base_link"/>

  <joint name="chassis_joint" type="fixed">
    <parent link="base_link"/>
    <child  link="chassis"/>
    <origin xyz="-0.1 0 0.15" rpy="0 0 0"/>
  </joint>

  <link name="chassis">
    <visual>
      <geometry><box size="1.2 0.6 0.25"/></geometry>
      <material name="blue"/>
    </visual>
    <collision>
      <geometry><box size="1.2 0.6 0.25"/></geometry>
    </collision>
    <inertial>
      <mass value="80.0"/>
      <inertia ixx="5.0" ixy="0" ixz="0" iyy="10.0" iyz="0" izz="12.0"/>
    </inertial>
  </link>

  <xacro:macro name="wheel" params="name x y">
    <joint name="${name}_joint" type="continuous">
      <parent link="base_link"/>
      <child  link="${name}"/>
      <origin xyz="${x} ${y} 0" rpy="0 0 0"/>
      <axis xyz="0 0 1"/>
    </joint>
    <link name="${name}">
      <visual>
        <geometry><cylinder radius="0.18" length="0.12"/></geometry>
        <material name="black"/>
      </visual>
      <collision>
        <geometry><cylinder radius="0.18" length="0.12"/></geometry>
      </collision>
      <inertial>
        <mass value="3.0"/>
        <inertia ixx="0.05" ixy="0" ixz="0" iyy="0.05" iyz="0" izz="0.08"/>
      </inertial>
    </link>
  </xacro:macro>

  <xacro:wheel name="front_left_wheel"  x=" 0.4" y=" 0.35"/>
  <xacro:wheel name="front_right_wheel" x=" 0.4" y="-0.35"/>
  <xacro:wheel name="rear_left_wheel"   x="-0.4" y=" 0.35"/>
  <xacro:wheel name="rear_right_wheel"  x="-0.4" y="-0.35"/>

  <joint name="lidar_joint" type="fixed">
    <parent link="chassis"/>
    <child  link="lidar_link"/>
    <origin xyz="0.5 0 0.2" rpy="0 0 0"/>
  </joint>

  <link name="lidar_link">
    <visual>
      <geometry><cylinder radius="0.05" length="0.08"/></geometry>
      <material name="grey"/>
    </visual>
    <inertial>
      <mass value="0.2"/>
      <inertia ixx="0.001" ixy="0" ixz="0" iyy="0.001" iyz="0" izz="0.001"/>
    </inertial>
  </link>

  <joint name="imu_joint" type="fixed">
    <parent link="chassis"/>
    <child  link="imu_link"/>
    <origin xyz="0 0 0.1" rpy="0 0 0"/>
  </joint>

  <link name="imu_link">
    <visual>
      <geometry><box size="0.05 0.05 0.02"/></geometry>
      <material name="grey"/>
    </visual>
    <inertial>
      <mass value="0.05"/>
      <inertia ixx="0.0001" ixy="0" ixz="0" iyy="0.0001" iyz="0" izz="0.0001"/>
    </inertial>
  </link>

  <gazebo>
    <plugin name="diff_drive" filename="libgazebo_ros_diff_drive.so">
      <left_joint>rear_left_wheel_joint</left_joint>
      <right_joint>rear_right_wheel_joint</right_joint>
      <wheel_separation>0.7</wheel_separation>
      <wheel_diameter>0.36</wheel_diameter>
      <max_wheel_torque>200</max_wheel_torque>
      <max_wheel_acceleration>1.0</max_wheel_acceleration>
      <command_topic>cmd_vel</command_topic>
      <publish_odom>true</publish_odom>
      <publish_odom_tf>true</publish_odom_tf>
      <publish_wheel_tf>true</publish_wheel_tf>
      <odometry_topic>odom</odometry_topic>
      <odometry_frame>odom</odometry_frame>
      <robot_base_frame>base_link</robot_base_frame>
    </plugin>
  </gazebo>

  <gazebo reference="lidar_link">
    <sensor name="lidar" type="ray">
      <always_on>true</always_on>
      <visualize>true</visualize>
      <update_rate>10</update_rate>
      <ray>
        <scan>
          <horizontal>
            <samples>360</samples>
            <resolution>1</resolution>
            <min_angle>-3.14159</min_angle>
            <max_angle>3.14159</max_angle>
          </horizontal>
        </scan>
        <range>
          <min>0.3</min>
          <max>30.0</max>
          <resolution>0.01</resolution>
        </range>
      </ray>
      <plugin name="lidar_plugin" filename="libgazebo_ros_ray_sensor.so">
        <ros><remapping>~/out:=scan</remapping></ros>
        <output_type>sensor_msgs/LaserScan</output_type>
        <frame_name>lidar_link</frame_name>
      </plugin>
    </sensor>
  </gazebo>

  <gazebo reference="imu_link">
    <sensor name="imu_sensor" type="imu">
      <always_on>true</always_on>
      <update_rate>50</update_rate>
      <plugin name="imu_plugin" filename="libgazebo_ros_imu_sensor.so">
        <ros><remapping>~/out:=imu/data</remapping></ros>
        <frame_name>imu_link</frame_name>
      </plugin>
    </sensor>
  </gazebo>

</robot>
